import { callAi, callAiEnv } from "call-ai";
import { describe, expect, assert } from "vitest";
import { itif } from "../test-helper.js";

// Configure retry settings for flaky tests

// Skip tests if no API key is available

// Timeout for individual test
const TIMEOUT = 30000;

describe("Error handling integration tests", () => {
  const haveApiKey = callAiEnv.CALLAI_API_KEY;
  // Test default model (should succeed)
  itif(!!haveApiKey)(
    "should succeed with default model",
    async () => {
      // Make a simple API call with no model specified
      const result = await callAi("Write a short joke about programming.", {
        apiKey: callAiEnv.CALLAI_API_KEY,
        // No model specified - should use default
      });

      // Verify response
      expect(typeof result).toBe("string");
      expect((result as string).length).toBeGreaterThan(10);
    },
    TIMEOUT,
  );

  // Test with invalid model (should throw an error)
  itif(!!haveApiKey)(
    "should throw error with invalid model",
    async () => {
      // Attempt API call with a non-existent model
      await expect(async () => {
        await callAi("Write a short joke about programming.", {
          apiKey: callAiEnv.CALLAI_API_KEY,
          model: "fake-model-that-does-not-exist",
          skipRetry: true, // Skip retry mechanism to force the error
        });
      }).rejects.toThrow();
    },
    TIMEOUT,
  );

  // Test streaming with invalid model (should also throw an error)
  itif(!!haveApiKey)(
    "should throw error with invalid model in streaming mode",
    async () => {
      // Attempt streaming API call with a non-existent model
      await expect(async () => {
        const generator = callAi("Write a short joke about programming.", {
          apiKey: callAiEnv.CALLAI_API_KEY,
          model: "fake-model-that-does-not-exist",
          stream: true,
          skipRetry: true, // Skip retry mechanism to force the error
        });

        // Try to consume the generator
        // Cast to AsyncGenerator to ensure TypeScript recognizes it properly
        const asyncGenerator = generator as unknown as AsyncGenerator<string, string, unknown>;

        for await (const _ of asyncGenerator) {
          // This should throw before yielding any chunks
        }
      }).rejects.toThrow();
    },
    TIMEOUT,
  );

  // Test error message contents
  itif(!!haveApiKey)(
    "should include HTTP status in error message",
    async () => {
      const fakeModelId = "fake-model-that-does-not-exist";

      // Attempt API call with a non-existent model
      try {
        await callAi("Write a short joke about programming.", {
          apiKey: callAiEnv.CALLAI_API_KEY,
          model: fakeModelId,
          skipRetry: true, // Skip retry mechanism to force the error
        });
        // If we get here, fail the test
        assert.fail("Should have thrown an error");
      } catch (error) {
        // Verify error message contains useful information
        expect(error instanceof Error).toBe(true);
        if (error instanceof Error) {
          // With the new error handling, we should see the HTTP status code
          expect(error.message).toContain("HTTP error");
          expect(error.message).toContain("400"); // Bad Request status code
        } else {
          assert.fail("Error is not an Error instance");
        }
      }
    },
    TIMEOUT,
  );

  // Test with debug option for error logging
  itif(!!haveApiKey)(
    "should handle error with debug option",
    async () => {
      // Spy on console.error
      // const consoleErrorSpy = vitest.spyOn(console, "error");

      // Attempt API call with a non-existent model and debug enabled
      try {
        await callAi("Write a short joke about programming.", {
          apiKey: callAiEnv.CALLAI_API_KEY,
          model: "fake-model-that-does-not-exist",
          skipRetry: true, // Skip retry mechanism to force the error
          debug: true, // Enable debug mode
        });
        // If we get here, fail the test
        assert.fail("Should have thrown an error");
      } catch (error) {
        // Verify console.error was called at least once (debug mode)
        // expect(consoleErrorSpy).toHaveBeenCalled();
        // Additional check to verify it's an Error instance
        expect(error instanceof Error).toBe(true);
      } finally {
        // Restore the original console.error
        // consoleErrorSpy.mockRestore();
      }
    },
    TIMEOUT,
  );

  // Test JSON parsing error with streaming and invalid model
  itif(!!haveApiKey)(
    "should reproduce the JSON parsing error seen in streaming mode",
    async () => {
      try {
        // Create generator with invalid model in streaming mode
        const generator = callAi("Write a short joke about programming.", {
          apiKey: callAiEnv.CALLAI_API_KEY,
          model: "fake-model-that-does-not-exist",
          stream: true,
          skipRetry: true, // Skip retry mechanism to force the error
          debug: true, // Enable debug mode
        });

        // Collect all streaming responses
        let finalResponse = "";
        // Try to consume generator - may fail during consumption
        try {
          const asyncGenerator = generator as unknown as AsyncGenerator<string, string, unknown>;
          for await (const chunk of asyncGenerator) {
            finalResponse = chunk;
            console.log(`Received chunk: ${chunk}`);
          }

          // If we get here, test what happens with JSON parsing
          console.log(`Final response (${finalResponse.length} chars): ${finalResponse}`);
          JSON.parse(finalResponse);

          // If we reach here, the JSON parsing unexpectedly succeeded
          assert.fail("JSON parsing should have failed but succeeded");
        } catch (streamError) {
          // We expect a SyntaxError from JSON.parse
          if (streamError instanceof SyntaxError) {
            // This is the expected path - JSON parsing should fail
            console.log("Expected error:", streamError.message);
            expect(streamError.message).toContain("Unexpected end of JSON");
          } else {
            // If it's another type of error, re-throw it to be caught by outer try/catch
            throw streamError;
          }
        }
      } catch (error) {
        // This catches any errors thrown before or during streaming
        if (error instanceof Error) {
          console.log("Outer error type:", error.constructor.name);
          console.log("Outer error message:", error.message);

          // If we want to fail the test when the streaming itself throws (rather than JSON.parse)
          // we could uncomment this line:
          // assert.fail(`Streaming should not throw directly but should return invalid JSON: ${error.message}`);
        } else {
          console.log("Unexpected non-Error object thrown:", error);
        }
      }
    },
    TIMEOUT,
  );

  // Test trying to mimic the React app's behavior more closely
  itif(!!haveApiKey)(
    "should mimic React app error handling with streaming",
    async () => {
      // We'll use a Promise to simulate React's async state updates
      let responseText = "";
      let errorMessage: string | null = null;

      const runGeneratorWithReactPatterns = async () => {
        try {
          // Wrap this in its own try/catch like React app does
          try {
            // Create generator with invalid model
            console.log("Creating generator...");
            const generator = callAi("Write a short joke about programming.", {
              apiKey: callAiEnv.CALLAI_API_KEY,
              model: "fake-model-that-does-not-exist",
              stream: true,
              skipRetry: true,
              debug: true,
              schema: {
                // Adding schema like in the React app
                properties: { text: { type: "string" } },
              },
            });

            console.log("Generator created, consuming chunks...");
            // This mimics React's state updates
            const asyncGenerator = generator as unknown as AsyncGenerator<string, string, unknown>;
            for await (const chunk of asyncGenerator) {
              responseText = chunk;
              console.log(`Updated response: ${responseText}`);
            }

            // Try to parse the final response
            console.log("Streaming completed, parsing JSON...");
            if (responseText) {
              const parsed = JSON.parse(responseText);
              console.log("Parsed JSON:", parsed);
            }
          } catch (innerError) {
            if (innerError instanceof Error) {
              console.log("Inner error caught:", innerError.message);
            } else {
              console.log("Inner error caught (not an Error):", String(innerError));
            }
            throw innerError; // Re-throw to outer catch
          }
        } catch (outerError) {
          // Set error message like React would do
          if (outerError instanceof Error) {
            console.log("Outer error caught:", outerError.message);
            errorMessage = outerError.message;

            if (outerError instanceof SyntaxError) {
              console.log("Got a SyntaxError - JSON parsing failed");
            } else {
              console.log("Error was not a SyntaxError:", outerError.constructor.name);
            }
          } else {
            console.log("Outer error caught (not an Error):", String(outerError));
            errorMessage = String(outerError);
          }
        }
      };

      // Run the simulated React code
      await runGeneratorWithReactPatterns();

      // Check results
      console.log("Final state - responseText:", responseText);
      console.log("Final state - errorMessage:", errorMessage);

      // We want to observe what happens, not necessarily fail/pass based on specific criteria
      expect(true).toBe(true); // Always passes
    },
    TIMEOUT,
  );

  itif(!!haveApiKey)(
    "should explore AsyncGenerator error handling patterns",
    async () => {
      // This test explores how errors propagate through AsyncGenerator in different patterns
      console.log("\n=== AsyncGenerator Error Handling Patterns ===");

      let responseText = "";
      let errorCaught = false;

      try {
        // First approach: Create the generator but don't immediately use it
        // This is closer to how browser environments might handle the code
        console.log("Step 1: Creating generator without immediate usage");
        // Explicitly type as AsyncGenerator to fix TypeScript errors
        const generator = callAi("Write a haiku", {
          stream: true,
          debug: true,
          model: "fake-model-that-does-not-exist",
          skipRetry: true,
          apiKey: callAiEnv.CALLAI_API_KEY,
        }) as unknown as AsyncGenerator<string, string, unknown>;

        console.log("Generator created, properties:", Object.getOwnPropertyNames(generator));

        // Delay the iteration slightly to mimic browser async behavior
        await new Promise((resolve) => setTimeout(resolve, 10));

        console.log("Step 2: Beginning manual iteration");

        // Try manual iteration with explicit next() calls instead of for-await
        try {
          let result: IteratorResult<string, string>;
          let isDone = false;

          // Loop until we're done or hit an error
          while (!isDone) {
            console.log("Calling generator.next()");
            result = await generator.next();
            console.log("next() returned:", {
              done: result.done,
              valueType: typeof result.value,
              valueLength: result.value ? result.value.length : 0,
            });

            if (result.done) {
              console.log("Generator iteration complete");
              isDone = true;
              responseText = result.value;
            } else {
              responseText = result.value;
              console.log(`Received chunk: ${responseText.substring(0, 30)}...`);
            }
          }

          console.log("Step 3: Completed iteration without errors");
          console.log(`Final response (${responseText.length} chars): ${responseText}`);

          // If we get here, try parsing the response
          try {
            console.log("Attempting to parse response as JSON");
            JSON.parse(responseText);
            console.log("JSON parsing succeeded unexpectedly");
          } catch (parseError: unknown) {
            // Properly type the error
            const error = parseError as Error;
            console.log("JSON parse error as expected:", error.message);
            errorCaught = true;
            expect(error.message).toContain("Unexpected");
          }
        } catch (iterError: unknown) {
          // Properly type the error
          const error = iterError as Error;
          console.log("Error during iteration:", error.constructor.name, error.message);
          errorCaught = true;
          expect(error.message).toContain("API returned error 400");
        }
      } catch (outerError: unknown) {
        // Properly type the error
        const error = outerError as Error;
        console.log("Outer error during generator creation:", error.message);
        errorCaught = true;
        expect(error.message).toContain("API returned error 400");
      }

      console.log("Final state - responseText:", responseText);
      console.log("Final state - errorCaught:", errorCaught);

      // We expect some form of error to be caught
      expect(errorCaught).toBe(true);
    },
    TIMEOUT,
  );
});
